Workbook

Sheet Por Recursos
B1: Presupuesto de Proyecto | G1: Clinica Veterinaria Pucara
B2: Elaborado por: Equipo de desarrollo numero 4 | E2: % Reserva de Contingencia | H2: ='Presupuesto Detallado'!I2 -> 0.1
B3: Líder del Proyecto: Jonathan Palma | E3: Presupuesto | G3: Reservas | H3: Total
B4: Fecha de Inicio: | D4: Total | E4: =H7+H20 -> 3445000 | G4: =E4*H2 -> 344500 | H4: =SUM(E4:G4) -> 3789500
B6: Categoría | C6: Recurso | E6: Tipo de Unidades | F6: Unidades | G6: Tasa | H6: Presupuesto
B7: Costos Directos | H7: =H8+H14+H17+H21 -> 3445000
B8: Labor (Personal) | H8: =SUM(H9+H10+H11) -> 3367000
C9: Jefe de Proyecto | E9: Horas | F9: ='Presupuesto Detallado'!G8+'Presupuesto Detallado'!G9+'Presupuesto Detallado'!G10+'Presupuesto Detallado'!G11+'Presupuesto Detallado'!G12+'Presupuesto Detallado'!G13+'Presupuesto Detallado'!G18+'Presupuesto Detallado'!G21+'Presupuesto Detallado'!G25+'Presupuesto Detallado'!G28+'Presupuesto Detallado'!G33+'Presupuesto Detallado'!G41+'Presupuesto Detallado'!G42+'Presupuesto Detallado'!G44+'Presupuesto Detallado'!G46+'Presupuesto Detallado'!G47 -> 112 | G9: 9000 | H9: =F9*G9 -> 1008000
C10: Programador Backend y BD | E10: Horas | F10: ='Presupuesto Detallado'!G15+'Presupuesto Detallado'!G16+'Presupuesto Detallado'!G17+'Presupuesto Detallado'!G22+'Presupuesto Detallado'!G24+'Presupuesto Detallado'!G27+'Presupuesto Detallado'!G30+'Presupuesto Detallado'!G35+'Presupuesto Detallado'!G37+'Presupuesto Detallado'!G38+'Presupuesto Detallado'!G40+'Presupuesto Detallado'!G45 -> 182 | G10: 8000 | H10: =F10*G10 -> 1456000
C11: Programador Frontend | E11: Horas | F11: ='Presupuesto Detallado'!G20+'Presupuesto Detallado'!G23+'Presupuesto Detallado'!G29+'Presupuesto Detallado'!G31+'Presupuesto Detallado'!G32+'Presupuesto Detallado'!G36+'Presupuesto Detallado'!G39 -> 129 | G11: 7000 | H11: =F11*G11 -> 903000
B14: Materiales | H14: =SUM(H15:H16) -> 20000
C15: Materiales de capacitación (manual de usuario) | E15: Unidad | F15: 1 | G15: 20000 | H15: =F15*G15 -> 20000
B17: Licencias | H17: =SUM(H18:H19) -> 38000
C18: Hosting | E18: Año | F18: 1 | G18: 25000 | H18: =F18*G18 -> 25000
C19: Dominio | E19: Año | F19: 1 | G19: 13000 | H19: =F19*G19 -> 13000
B20: Costos Indirectos
B21: Gastos de Cierre y Auditoría | H21: =SUM(H22:H23) -> 20000
C22: Evaluación y cierre del proyecto | E22: Servicio | F22: Servicio | H22: 20000

Sheet Presupuesto Detallado
B1: Presupuesto de Proyecto | G1: Clinica Veterinaria Pucara
B2: Elaborado por: Equipo de desarrollo numero 4 | G2: % Reserva de Contingencia | I2: 0.1
B3: Líder del Proyecto: Jonathan Palma | G3: Presupuesto | H3: Reservas | I3: Total
B4: Fecha de Inicio: 10/10/2025 | E4: Total | G4: ='Por Recursos'!H7 -> 3445000 | H4: =G4*I2 -> 344500 | I4: =SUM(G4:H4) -> 3789500
B6: Código | C6: Tarea / Actividad | D6: Elemento | E6: Tipo de Recurso | F6: Tipo de Unidades | G6: Unidades | H6: Tasa | I6: Presupuesto
B7: 1 | C7: FASE DE INICIO Y PLANIFICACIÓN | I7: =I8+I9+I10+I11+I12+I13 -> 360006
B8: 1.1 | C8: Redacción del informe técnico inicial | D8: Jefe de Proyecto (Jonathan Palma) | E8: Labor (Personal) | F8: Horas | G8: 10 | H8: 9000 | I8: =G8*H8 -> 90000
B9: 1.2 | C9: Análisis preliminar del caso | D9: Jefe de Proyecto (Jonathan Palma) | E9: Labor (Personal) | F9: Horas | G9: 9 | H9: 9000 | I9: =G9*H9 -> 81000
B10: 1.3 | C10: Preparación documentación | D10: Jefe de Proyecto (Jonathan Palma) | E10: Labor (Personal) | F10: Horas | G10: 7 | H10: 9000 | I10: =G10*H10 -> 63000
B11: 1.4 | C11: Levantamiento de requerimientos con la clínica | D11: Jefe de Proyecto (Jonathan Palma) | E11: Labor (Personal) | F11: Horas | G11: 6 | H11: 9000 | I11: =G11*H11 -> 54000
B12: 1.5 | C12: Kick-off y Acta de reunión | D12: Jefe de Proyecto (Jonathan Palma) | E12: Labor (Personal) | F12: Horas | G12: 7 | H12: 9000 | I12: =G12*H12 -> 63000
B13: 1.6 | C13: Cierre y entrega documentación fase 1 | D13: Jefe de Proyecto (Jonathan Palma) | E13: Labor (Personal) | F13: Horas | G13: 6 | H13: 9000 | I13: =G13+H13 -> 9006
B14: 2 | C14: FASE SPRINT 0 | I14: =I15+I16+I17+I18 -> 537000
B15: 2.1 | C15: Diseño entidad-relación y modelo de datos | D15: Programador Backend & BD (Sergio Valdivia) | E15: Labor (Personal) | F15: Horas | G15: 22 | H15: 8000 | I15: =G15*H15 -> 176000
B16: 2.2 | C16: Configuración Java + PostgreSQL | D16: Programador Backend & BD (Sergio Valdivia) | E16: Labor (Personal) | F16: Horas | G16: 18 | H16: 8000 | I16: =G16*H16 -> 144000
B17: 2.3 | C17: Implementación de módulos iniciales | D17: Programador Backend & BD (Sergio Valdivia) | E17: Labor (Personal) | F17: Horas | G17: 17 | H17: 8000 | I17: =G17*H17 -> 136000
B18: 2.4 | C18: Reuniones de planificación y control del Gantt | D18: Jefe de Proyecto (Jonathan Palma) | E18: Labor (Personal) | F18: Horas | G18: 9 | H18: 9000 | I18: =G18*H18 -> 81000
B19: 3 | C19: FASE SPRINT 1 – Desarrollo inicial del sistema | I19: =I20+I21+I22+I23+I24+I25 -> 937000
B20: 3.1 | C20: Prototipo frontend | D20: Programador Frontend (Renato Olivera) | E20: Labor (Personal) | F20: Horas | G20: 20 | H20: 7000 | I20: =G20*H20 -> 140000
B21: 3.2 | C21: Validación con cliente | D21: Jefe de proyectos (Jonathan Palma) | E21: Labor (Personal) | F21: Horas | G21: 8 | H21: 9000 | I21: =G21*H21 -> 72000
B22: 3.3 | C22: Desarrollo de backend: registro, login y citas | D22: Programador Backend & BD (Sergio Valdivia) | E22: Labor (Personal) | F22: Horas | G22: 27 | H22: 8000 | I22: =G22*H22 -> 216000
B23: 3.4 | C23: Implementación interfaz responsiva (React + Vite) | D23: Programador Frontend (Renato Olivera) | E23: Labor (Personal) | F23: Horas | G23: 30 | H23: 7000 | I23: =G23*H23 -> 210000
B24: 3.5 | C24: Integración inicial frontend–backend | D24: Programador Backend & BD (Sergio Valdivia) | E24: Labor (Personal) | F24: Horas | G24: 25 | H24: 8000 | I24: =G24*H24 -> 200000
B25: 3.6 | C25: Revisión del avance, riesgos y soporte funcional | D25: Jefe de proyectos (Jonathan Palma) | E25: Labor (Personal) | F25: Horas | G25: 11 | H25: 9000 | I25: =G25*H25 -> 99000
B26: 4 | C26: FASE SPRINT 2 – Desarrollo intermedio | I26: =I27+I28+I29+I30+I31+I32+I33 -> 835000
B27: 4.1 | C27: CRUD completo para modulo clientes y mascotas | D27: Programador Backend & BD (Sergio Valdivia) | E27: Labor (Personal) | F27: Horas | G27: 17 | H27: 8000 | I27: =G27*H27 -> 136000
B28: 4.2 | C28: Reunion para revision de avances y flujo logico | D28: Jefe de Proyecto (Jonathan Palma) | E28: Labor (Personal) | F28: Horas | G28: 6 | H28: 9000 | I28: =G28*H28 -> 54000
B29: 4.3 | C29: Vista administracion completa para el veterinario | D29: Programador Frontend (Renato Olivera) | E29: Labor (Personal) | F29: Horas | G29: 25 | H29: 7000 | I29: =G29*H29 -> 175000
B30: 4.4 | C30: Integración backend avanzada | D30: Programador Backend & BD (Sergio Valdivia) | E30: Labor (Personal) | F30: Horas | G30: 22 | H30: 8000 | I30: =H30*G30 -> 176000
B31: 4.5 | C31: Vista para recepcionista | D31: Programador Frontend (Renato Olivera) | E31: Labor (Personal) | F31: Horas | G31: 18 | H31: 7000 | I31: =H31*G31 -> 126000
B32: 4.6 | C32: Mejoras visuales y UX | D32: Programador Frontend (Renato Olivera) | E32: Labor (Personal) | F32: Horas | G32: 15 | H32: 7000 | I32: =H32*G32 -> 105000
B33: 4.7 | C33: Validación funcional y revisión UX | D33: Jefe de Proyecto (Jonathan Palma) | E33: Labor (Personal) | F33: Horas | G33: 7 | H33: 9000 | I33: =G33*H33 -> 63000
B34: 5 | C34: FASE SPRINT 3 – Desarrollo avanzado | I34: =I35+I36+I37+I38+I39+I40+I41+I42 -> 530000
B35: 5.1 | C35: Modulo de ficha clínica | D35: Programador Backend & BD (Sergio Valdivia) | E35: Labor (Personal) | F35: Horas | G35: 9 | H35: 8000 | I35: =G35*H35 -> 72000
B36: 5.2 | C36: Certificados digitales descargables | D36: Programador Frontend (Renato Olivera) | E36: Labor (Personal) | F36: Horas | G36: 16 | H36: 7000 | I36: =G36*H36 -> 112000
B37: 5.3 | C37: Implementar notificaciones automaticas (WhatsApp) | D37: Programador Backend & BD (Sergio Valdivia) | E37: Labor (Personal) | F37: Horas | G37: 8 | H37: 8000 | I37: =H37*G37 -> 64000
B38: 5.4 | C38: Modulo de inventario | D38: Programador Backend & BD (Sergio Valdivia) | E38: Labor (Personal) | F38: Horas | G38: 9 | H38: 8000 | I38: =H38*G38 -> 72000
B39: 5.5 | C39: Integración final frontend–backend | D39: Programador Frontend (Renato Olivera) | E39: Labor (Personal) | F39: Horas | G39: 5 | H39: 7000 | I39: =H39*G39 -> 35000
B40: 5.6 | C40: Integración final Backend-Frontend | D40: Programador Backend & BD (Sergio Valdivia) | E40: Labor (Personal) | F40: Horas | G40: 5 | H40: 8000 | I40: =H40*G40 -> 40000
B41: 5.7 | C41: Validacion de integraciones | D41: Jefe de Proyecto (Jonathan Palma) | E41: Labor (Personal) | F41: Horas | G41: 8 | H41: 9000 | I41: =G41*H41 -> 72000
...

Sheet Datos
B1: Presupuesto de Proyecto | D1: Clinica Veterinaria Pucara
B3: Líder del Proyecto: Jonathan Palma
B4: Fecha de Inicio: 10/10/2025
B6: Elemento | C6: Tipo de Recurso | D6: Tipo de Unidades | E6: Tasa
B8: Jefe de Proyecto (Jonathan Palma) | C8: Labor (Personal) | D8: Horas / Jornadas | E8: 9000
B9: Programador Backend & BD (Sergio Valdivia) | C9: Labor (Personal) | D9: Horas / Jornadas | E9: 8000
B10: Programador Frontend (Renato Olivera) | C10: Labor (Personal) | D10: Horas / Jornadas | E10: 7000
B11: Material 1 – Hosting | C11: Licencias | D11: Año | E11: 25000
B12: Material 2 – Dominio | C12: Licencias | D12: Año | E12: 13000
